2021-02-11 23:35:14,196 INFO: Microblog startup [in /Users/shreyas/Desktop/microblog/app/__init__.py:47]
2021-02-11 23:35:39,603 ERROR: Exception on /reset_password_request [POST] [in /Users/shreyas/Desktop/microblog/venv/lib/python3.9/site-packages/flask/app.py:1891]
Traceback (most recent call last):
  File "/Users/shreyas/Desktop/microblog/venv/lib/python3.9/site-packages/flask/app.py", line 2447, in wsgi_app
    response = self.full_dispatch_request()
  File "/Users/shreyas/Desktop/microblog/venv/lib/python3.9/site-packages/flask/app.py", line 1952, in full_dispatch_request
    rv = self.handle_user_exception(e)
  File "/Users/shreyas/Desktop/microblog/venv/lib/python3.9/site-packages/flask/app.py", line 1821, in handle_user_exception
    reraise(exc_type, exc_value, tb)
  File "/Users/shreyas/Desktop/microblog/venv/lib/python3.9/site-packages/flask/_compat.py", line 39, in reraise
    raise value
  File "/Users/shreyas/Desktop/microblog/venv/lib/python3.9/site-packages/flask/app.py", line 1950, in full_dispatch_request
    rv = self.dispatch_request()
  File "/Users/shreyas/Desktop/microblog/venv/lib/python3.9/site-packages/flask/app.py", line 1936, in dispatch_request
    return self.view_functions[rule.endpoint](**req.view_args)
  File "/Users/shreyas/Desktop/microblog/app/routes.py", line 166, in reset_password_request
    send_password_reset_email(user)
  File "/Users/shreyas/Desktop/microblog/app/email.py", line 13, in send_password_reset_email
    send_email('[Microblog] Reset Your Password',
  File "/Users/shreyas/Desktop/microblog/app/email.py", line 9, in send_email
    mail.send(msg)
  File "/Users/shreyas/Desktop/microblog/venv/lib/python3.9/site-packages/flask_mail.py", line 491, in send
    with self.connect() as connection:
  File "/Users/shreyas/Desktop/microblog/venv/lib/python3.9/site-packages/flask_mail.py", line 144, in __enter__
    self.host = self.configure_host()
  File "/Users/shreyas/Desktop/microblog/venv/lib/python3.9/site-packages/flask_mail.py", line 165, in configure_host
    host.login(self.mail.username, self.mail.password)
  File "/usr/local/Cellar/python@3.9/3.9.1/Frameworks/Python.framework/Versions/3.9/lib/python3.9/smtplib.py", line 734, in login
    raise last_exception
  File "/usr/local/Cellar/python@3.9/3.9.1/Frameworks/Python.framework/Versions/3.9/lib/python3.9/smtplib.py", line 723, in login
    (code, resp) = self.auth(
  File "/usr/local/Cellar/python@3.9/3.9.1/Frameworks/Python.framework/Versions/3.9/lib/python3.9/smtplib.py", line 646, in auth
    raise SMTPAuthenticationError(code, resp)
smtplib.SMTPAuthenticationError: (534, b'5.7.9 Application-specific password required. Learn more at\n5.7.9  https://support.google.com/mail/?p=InvalidSecondFactor d22sm4981989qtp.34 - gsmtp')
2021-02-11 23:39:19,946 INFO: Microblog startup [in /Users/shreyas/Desktop/microblog/app/__init__.py:47]
2021-03-19 21:59:20,542 INFO: Microblog startup [in /Users/shreyas/Desktop/microblog/app/__init__.py:54]
2021-03-19 22:03:54,807 INFO: Microblog startup [in /Users/shreyas/Desktop/microblog/app/__init__.py:54]
2021-03-19 22:04:05,368 INFO: Microblog startup [in /Users/shreyas/Desktop/microblog/app/__init__.py:54]
2021-03-19 22:23:58,269 INFO: Microblog startup [in /Users/shreyas/Desktop/microblog/app/__init__.py:54]
2021-03-19 22:24:05,293 ERROR: Exception on /messages [GET] [in /Users/shreyas/Desktop/microblog/venv/lib/python3.9/site-packages/flask/app.py:1891]
Traceback (most recent call last):
  File "/Users/shreyas/Desktop/microblog/venv/lib/python3.9/site-packages/flask/app.py", line 2447, in wsgi_app
    response = self.full_dispatch_request()
  File "/Users/shreyas/Desktop/microblog/venv/lib/python3.9/site-packages/flask/app.py", line 1952, in full_dispatch_request
    rv = self.handle_user_exception(e)
  File "/Users/shreyas/Desktop/microblog/venv/lib/python3.9/site-packages/flask/app.py", line 1821, in handle_user_exception
    reraise(exc_type, exc_value, tb)
  File "/Users/shreyas/Desktop/microblog/venv/lib/python3.9/site-packages/flask/_compat.py", line 39, in reraise
    raise value
  File "/Users/shreyas/Desktop/microblog/venv/lib/python3.9/site-packages/flask/app.py", line 1950, in full_dispatch_request
    rv = self.dispatch_request()
  File "/Users/shreyas/Desktop/microblog/venv/lib/python3.9/site-packages/flask/app.py", line 1936, in dispatch_request
    return self.view_functions[rule.endpoint](**req.view_args)
  File "/Users/shreyas/Desktop/microblog/venv/lib/python3.9/site-packages/flask_login/utils.py", line 272, in decorated_view
    return func(*args, **kwargs)
  File "/Users/shreyas/Desktop/microblog/app/routes.py", line 210, in messages
    page, current_app.config['POSTS_PER_PAGE'], False)
NameError: name 'current_app' is not defined
2021-03-19 22:26:39,970 INFO: Microblog startup [in /Users/shreyas/Desktop/microblog/app/__init__.py:54]
